[0m17:16:15.804476 [debug] [MainThread]: Sending event: {'category': 'dbt', 'action': 'invocation', 'label': 'start', 'context': [<snowplow_tracker.self_describing_json.SelfDescribingJson object at 0x0000015CBF4ECEF0>, <snowplow_tracker.self_describing_json.SelfDescribingJson object at 0x0000015CBF4ED100>, <snowplow_tracker.self_describing_json.SelfDescribingJson object at 0x0000015CBF4ED1C0>]}


============================== 17:16:15.813628 | d787c601-6772-47f9-ae19-eb5d61a4c921 ==============================
[0m17:16:15.813628 [info ] [MainThread]: Running with dbt=1.7.7
[0m17:16:15.813628 [debug] [MainThread]: running dbt with arguments {'printer_width': '80', 'indirect_selection': 'eager', 'write_json': 'True', 'log_cache_events': 'False', 'partial_parse': 'True', 'cache_selected_only': 'False', 'profiles_dir': 'C:\\Users\\pc\\.dbt', 'debug': 'False', 'version_check': 'True', 'log_path': 'logs', 'warn_error': 'None', 'fail_fast': 'False', 'use_colors': 'True', 'use_experimental_parser': 'False', 'no_print': 'None', 'quiet': 'False', 'warn_error_options': 'WarnErrorOptions(include=[], exclude=[])', 'static_parser': 'True', 'invocation_command': 'dbt init', 'log_format': 'default', 'target_path': 'None', 'introspect': 'True', 'send_anonymous_usage_stats': 'True'}
[0m17:16:46.877859 [debug] [MainThread]: Starter project path: C:\Users\pc\AppData\Local\Programs\Python\Python312\Lib\site-packages\dbt\include\starter_project
[0m17:16:46.923793 [info ] [MainThread]: 
Your new dbt project "SMA_BI" was created!

For more information on how to configure the profiles.yml file,
please consult the dbt documentation here:

  https://docs.getdbt.com/docs/configure-your-profile

One more thing:

Need help? Don't hesitate to reach out to us via GitHub issues or on Slack:

  https://community.getdbt.com/

Happy modeling!

[0m17:16:46.923793 [info ] [MainThread]: Setting up your profile.
[0m17:16:46.923793 [error] [MainThread]: Encountered an error:
mapping values are not allowed here
  in "C:\Users\pc\.dbt\profiles.yml", line 14, column 12
[0m17:16:47.071205 [error] [MainThread]: Traceback (most recent call last):
  File "C:\Users\pc\AppData\Local\Programs\Python\Python312\Lib\site-packages\dbt\cli\requires.py", line 91, in wrapper
    result, success = func(*args, **kwargs)
                      ^^^^^^^^^^^^^^^^^^^^^
  File "C:\Users\pc\AppData\Local\Programs\Python\Python312\Lib\site-packages\dbt\cli\requires.py", line 76, in wrapper
    return func(*args, **kwargs)
           ^^^^^^^^^^^^^^^^^^^^^
  File "C:\Users\pc\AppData\Local\Programs\Python\Python312\Lib\site-packages\dbt\cli\main.py", line 515, in init
    results = task.run()
              ^^^^^^^^^^
  File "C:\Users\pc\AppData\Local\Programs\Python\Python312\Lib\site-packages\dbt\task\init.py", line 344, in run
    self.setup_profile(profile_name)
  File "C:\Users\pc\AppData\Local\Programs\Python\Python312\Lib\site-packages\dbt\task\init.py", line 250, in setup_profile
    if not self.check_if_can_write_profile(profile_name=profile_name):
           ^^^^^^^^^^^^^^^^^^^^^^^^^^^^^^^^^^^^^^^^^^^^^^^^^^^^^^^^^^
  File "C:\Users\pc\AppData\Local\Programs\Python\Python312\Lib\site-packages\dbt\task\init.py", line 211, in check_if_can_write_profile
    profiles = yaml.safe_load(f) or {}
               ^^^^^^^^^^^^^^^^^
  File "C:\Users\pc\AppData\Local\Programs\Python\Python312\Lib\site-packages\yaml\__init__.py", line 125, in safe_load
    return load(stream, SafeLoader)
           ^^^^^^^^^^^^^^^^^^^^^^^^
  File "C:\Users\pc\AppData\Local\Programs\Python\Python312\Lib\site-packages\yaml\__init__.py", line 81, in load
    return loader.get_single_data()
           ^^^^^^^^^^^^^^^^^^^^^^^^
  File "C:\Users\pc\AppData\Local\Programs\Python\Python312\Lib\site-packages\yaml\constructor.py", line 49, in get_single_data
    node = self.get_single_node()
           ^^^^^^^^^^^^^^^^^^^^^^
  File "C:\Users\pc\AppData\Local\Programs\Python\Python312\Lib\site-packages\yaml\composer.py", line 36, in get_single_node
    document = self.compose_document()
               ^^^^^^^^^^^^^^^^^^^^^^^
  File "C:\Users\pc\AppData\Local\Programs\Python\Python312\Lib\site-packages\yaml\composer.py", line 55, in compose_document
    node = self.compose_node(None, None)
           ^^^^^^^^^^^^^^^^^^^^^^^^^^^^^
  File "C:\Users\pc\AppData\Local\Programs\Python\Python312\Lib\site-packages\yaml\composer.py", line 84, in compose_node
    node = self.compose_mapping_node(anchor)
           ^^^^^^^^^^^^^^^^^^^^^^^^^^^^^^^^^
  File "C:\Users\pc\AppData\Local\Programs\Python\Python312\Lib\site-packages\yaml\composer.py", line 133, in compose_mapping_node
    item_value = self.compose_node(node, item_key)
                 ^^^^^^^^^^^^^^^^^^^^^^^^^^^^^^^^^
  File "C:\Users\pc\AppData\Local\Programs\Python\Python312\Lib\site-packages\yaml\composer.py", line 84, in compose_node
    node = self.compose_mapping_node(anchor)
           ^^^^^^^^^^^^^^^^^^^^^^^^^^^^^^^^^
  File "C:\Users\pc\AppData\Local\Programs\Python\Python312\Lib\site-packages\yaml\composer.py", line 127, in compose_mapping_node
    while not self.check_event(MappingEndEvent):
              ^^^^^^^^^^^^^^^^^^^^^^^^^^^^^^^^^
  File "C:\Users\pc\AppData\Local\Programs\Python\Python312\Lib\site-packages\yaml\parser.py", line 98, in check_event
    self.current_event = self.state()
                         ^^^^^^^^^^^^
  File "C:\Users\pc\AppData\Local\Programs\Python\Python312\Lib\site-packages\yaml\parser.py", line 428, in parse_block_mapping_key
    if self.check_token(KeyToken):
       ^^^^^^^^^^^^^^^^^^^^^^^^^^
  File "C:\Users\pc\AppData\Local\Programs\Python\Python312\Lib\site-packages\yaml\scanner.py", line 116, in check_token
    self.fetch_more_tokens()
  File "C:\Users\pc\AppData\Local\Programs\Python\Python312\Lib\site-packages\yaml\scanner.py", line 223, in fetch_more_tokens
    return self.fetch_value()
           ^^^^^^^^^^^^^^^^^^
  File "C:\Users\pc\AppData\Local\Programs\Python\Python312\Lib\site-packages\yaml\scanner.py", line 577, in fetch_value
    raise ScannerError(None, None,
yaml.scanner.ScannerError: mapping values are not allowed here
  in "C:\Users\pc\.dbt\profiles.yml", line 14, column 12

[0m17:16:47.090956 [debug] [MainThread]: Command `dbt init` failed at 17:16:47.090956 after 31.35 seconds
[0m17:16:47.090956 [debug] [MainThread]: Sending event: {'category': 'dbt', 'action': 'invocation', 'label': 'end', 'context': [<snowplow_tracker.self_describing_json.SelfDescribingJson object at 0x0000015CBF349B80>, <snowplow_tracker.self_describing_json.SelfDescribingJson object at 0x0000015CBF412F90>, <snowplow_tracker.self_describing_json.SelfDescribingJson object at 0x0000015CBEF0ED80>]}
[0m17:16:47.105064 [debug] [MainThread]: Flushing usage events
